2022-11-12 00:42:35,274 ERROR: Exception on /edit_profile [POST] [in /Users/ivylou/Desktop/pythonProject/testnet2/venv/lib/python3.8/site-packages/flask/app.py:1449]
Traceback (most recent call last):
  File "/Users/ivylou/Desktop/pythonProject/testnet2/venv/lib/python3.8/site-packages/sqlalchemy/engine/base.py", line 1819, in _execute_context
    self.dialect.do_execute(
  File "/Users/ivylou/Desktop/pythonProject/testnet2/venv/lib/python3.8/site-packages/sqlalchemy/engine/default.py", line 732, in do_execute
    cursor.execute(statement, parameters)
  File "/Users/ivylou/Desktop/pythonProject/testnet2/venv/lib/python3.8/site-packages/mysql/connector/cursor.py", line 561, in execute
    self._handle_result(self._connection.cmd_query(stmt))
  File "/Users/ivylou/Desktop/pythonProject/testnet2/venv/lib/python3.8/site-packages/mysql/connector/connection.py", line 990, in cmd_query
    result = self._handle_result(self._send_cmd(ServerCmd.QUERY, query))
  File "/Users/ivylou/Desktop/pythonProject/testnet2/venv/lib/python3.8/site-packages/mysql/connector/connection.py", line 784, in _handle_result
    raise get_exception(packet)
mysql.connector.errors.IntegrityError: 1062 (23000): Duplicate entry 'sam' for key 'users.ix_users_username'

The above exception was the direct cause of the following exception:

Traceback (most recent call last):
  File "/Users/ivylou/Desktop/pythonProject/testnet2/venv/lib/python3.8/site-packages/flask/app.py", line 2073, in wsgi_app
    response = self.full_dispatch_request()
  File "/Users/ivylou/Desktop/pythonProject/testnet2/venv/lib/python3.8/site-packages/flask/app.py", line 1519, in full_dispatch_request
    rv = self.handle_user_exception(e)
  File "/Users/ivylou/Desktop/pythonProject/testnet2/venv/lib/python3.8/site-packages/flask/app.py", line 1517, in full_dispatch_request
    rv = self.dispatch_request()
  File "/Users/ivylou/Desktop/pythonProject/testnet2/venv/lib/python3.8/site-packages/flask/app.py", line 1503, in dispatch_request
    return self.ensure_sync(self.view_functions[rule.endpoint])(**req.view_args)
  File "/Users/ivylou/Desktop/pythonProject/testnet2/venv/lib/python3.8/site-packages/flask_login/utils.py", line 290, in decorated_view
    return current_app.ensure_sync(func)(*args, **kwargs)
  File "/Users/ivylou/Desktop/pythonProject/testnet2/app/main/routes.py", line 72, in edit_profile
    db.session.commit()
  File "<string>", line 2, in commit
  File "/Users/ivylou/Desktop/pythonProject/testnet2/venv/lib/python3.8/site-packages/sqlalchemy/orm/session.py", line 1451, in commit
    self._transaction.commit(_to_root=self.future)
  File "/Users/ivylou/Desktop/pythonProject/testnet2/venv/lib/python3.8/site-packages/sqlalchemy/orm/session.py", line 829, in commit
    self._prepare_impl()
  File "/Users/ivylou/Desktop/pythonProject/testnet2/venv/lib/python3.8/site-packages/sqlalchemy/orm/session.py", line 808, in _prepare_impl
    self.session.flush()
  File "/Users/ivylou/Desktop/pythonProject/testnet2/venv/lib/python3.8/site-packages/sqlalchemy/orm/session.py", line 3383, in flush
    self._flush(objects)
  File "/Users/ivylou/Desktop/pythonProject/testnet2/venv/lib/python3.8/site-packages/sqlalchemy/orm/session.py", line 3523, in _flush
    transaction.rollback(_capture_exception=True)
  File "/Users/ivylou/Desktop/pythonProject/testnet2/venv/lib/python3.8/site-packages/sqlalchemy/util/langhelpers.py", line 70, in __exit__
    compat.raise_(
  File "/Users/ivylou/Desktop/pythonProject/testnet2/venv/lib/python3.8/site-packages/sqlalchemy/util/compat.py", line 208, in raise_
    raise exception
  File "/Users/ivylou/Desktop/pythonProject/testnet2/venv/lib/python3.8/site-packages/sqlalchemy/orm/session.py", line 3483, in _flush
    flush_context.execute()
  File "/Users/ivylou/Desktop/pythonProject/testnet2/venv/lib/python3.8/site-packages/sqlalchemy/orm/unitofwork.py", line 456, in execute
    rec.execute(self)
  File "/Users/ivylou/Desktop/pythonProject/testnet2/venv/lib/python3.8/site-packages/sqlalchemy/orm/unitofwork.py", line 630, in execute
    util.preloaded.orm_persistence.save_obj(
  File "/Users/ivylou/Desktop/pythonProject/testnet2/venv/lib/python3.8/site-packages/sqlalchemy/orm/persistence.py", line 237, in save_obj
    _emit_update_statements(
  File "/Users/ivylou/Desktop/pythonProject/testnet2/venv/lib/python3.8/site-packages/sqlalchemy/orm/persistence.py", line 1001, in _emit_update_statements
    c = connection._execute_20(
  File "/Users/ivylou/Desktop/pythonProject/testnet2/venv/lib/python3.8/site-packages/sqlalchemy/engine/base.py", line 1631, in _execute_20
    return meth(self, args_10style, kwargs_10style, execution_options)
  File "/Users/ivylou/Desktop/pythonProject/testnet2/venv/lib/python3.8/site-packages/sqlalchemy/sql/elements.py", line 332, in _execute_on_connection
    return connection._execute_clauseelement(
  File "/Users/ivylou/Desktop/pythonProject/testnet2/venv/lib/python3.8/site-packages/sqlalchemy/engine/base.py", line 1498, in _execute_clauseelement
    ret = self._execute_context(
  File "/Users/ivylou/Desktop/pythonProject/testnet2/venv/lib/python3.8/site-packages/sqlalchemy/engine/base.py", line 1862, in _execute_context
    self._handle_dbapi_exception(
  File "/Users/ivylou/Desktop/pythonProject/testnet2/venv/lib/python3.8/site-packages/sqlalchemy/engine/base.py", line 2043, in _handle_dbapi_exception
    util.raise_(
  File "/Users/ivylou/Desktop/pythonProject/testnet2/venv/lib/python3.8/site-packages/sqlalchemy/util/compat.py", line 208, in raise_
    raise exception
  File "/Users/ivylou/Desktop/pythonProject/testnet2/venv/lib/python3.8/site-packages/sqlalchemy/engine/base.py", line 1819, in _execute_context
    self.dialect.do_execute(
  File "/Users/ivylou/Desktop/pythonProject/testnet2/venv/lib/python3.8/site-packages/sqlalchemy/engine/default.py", line 732, in do_execute
    cursor.execute(statement, parameters)
  File "/Users/ivylou/Desktop/pythonProject/testnet2/venv/lib/python3.8/site-packages/mysql/connector/cursor.py", line 561, in execute
    self._handle_result(self._connection.cmd_query(stmt))
  File "/Users/ivylou/Desktop/pythonProject/testnet2/venv/lib/python3.8/site-packages/mysql/connector/connection.py", line 990, in cmd_query
    result = self._handle_result(self._send_cmd(ServerCmd.QUERY, query))
  File "/Users/ivylou/Desktop/pythonProject/testnet2/venv/lib/python3.8/site-packages/mysql/connector/connection.py", line 784, in _handle_result
    raise get_exception(packet)
sqlalchemy.exc.IntegrityError: (mysql.connector.errors.IntegrityError) 1062 (23000): Duplicate entry 'sam' for key 'users.ix_users_username'
[SQL: UPDATE users SET username=%(username)s WHERE users.id = %(users_id)s]
[parameters: {'username': 'sam', 'users_id': 4}]
(Background on this error at: https://sqlalche.me/e/14/gkpj)
2022-11-12 00:44:35,392 INFO: Testnet startup [in /Users/ivylou/Desktop/pythonProject/testnet2/app/__init__.py:60]
2022-11-13 19:28:27,573 INFO: Testnet startup [in /Users/ivylou/Desktop/pythonProject/testnet2/app/__init__.py:63]
2022-11-13 19:30:06,047 INFO: Testnet startup [in /Users/ivylou/Desktop/pythonProject/testnet2/app/__init__.py:63]
2022-11-13 19:30:06,047 INFO: Testnet startup [in /Users/ivylou/Desktop/pythonProject/testnet2/app/__init__.py:63]
2022-11-13 19:40:58,264 INFO: Testnet startup [in /Users/ivylou/Desktop/pythonProject/testnet2/app/__init__.py:63]
2022-11-13 19:42:34,702 INFO: Testnet startup [in /Users/ivylou/Desktop/pythonProject/testnet2/app/__init__.py:63]
2022-11-13 19:42:48,689 ERROR: Exception on /edit_profile [POST] [in /Users/ivylou/Desktop/pythonProject/testnet2/venv/lib/python3.8/site-packages/flask/app.py:1449]
Traceback (most recent call last):
  File "/Users/ivylou/Desktop/pythonProject/testnet2/venv/lib/python3.8/site-packages/sqlalchemy/engine/base.py", line 1819, in _execute_context
    self.dialect.do_execute(
  File "/Users/ivylou/Desktop/pythonProject/testnet2/venv/lib/python3.8/site-packages/sqlalchemy/engine/default.py", line 732, in do_execute
    cursor.execute(statement, parameters)
  File "/Users/ivylou/Desktop/pythonProject/testnet2/venv/lib/python3.8/site-packages/mysql/connector/cursor.py", line 561, in execute
    self._handle_result(self._connection.cmd_query(stmt))
  File "/Users/ivylou/Desktop/pythonProject/testnet2/venv/lib/python3.8/site-packages/mysql/connector/connection.py", line 990, in cmd_query
    result = self._handle_result(self._send_cmd(ServerCmd.QUERY, query))
  File "/Users/ivylou/Desktop/pythonProject/testnet2/venv/lib/python3.8/site-packages/mysql/connector/connection.py", line 784, in _handle_result
    raise get_exception(packet)
mysql.connector.errors.IntegrityError: 1062 (23000): Duplicate entry 'max' for key 'users.ix_users_username'

The above exception was the direct cause of the following exception:

Traceback (most recent call last):
  File "/Users/ivylou/Desktop/pythonProject/testnet2/venv/lib/python3.8/site-packages/flask/app.py", line 2073, in wsgi_app
    response = self.full_dispatch_request()
  File "/Users/ivylou/Desktop/pythonProject/testnet2/venv/lib/python3.8/site-packages/flask/app.py", line 1519, in full_dispatch_request
    rv = self.handle_user_exception(e)
  File "/Users/ivylou/Desktop/pythonProject/testnet2/venv/lib/python3.8/site-packages/flask/app.py", line 1517, in full_dispatch_request
    rv = self.dispatch_request()
  File "/Users/ivylou/Desktop/pythonProject/testnet2/venv/lib/python3.8/site-packages/flask/app.py", line 1503, in dispatch_request
    return self.ensure_sync(self.view_functions[rule.endpoint])(**req.view_args)
  File "/Users/ivylou/Desktop/pythonProject/testnet2/venv/lib/python3.8/site-packages/flask_login/utils.py", line 290, in decorated_view
    return current_app.ensure_sync(func)(*args, **kwargs)
  File "/Users/ivylou/Desktop/pythonProject/testnet2/app/main/routes.py", line 72, in edit_profile
    db.session.commit()
  File "<string>", line 2, in commit
  File "/Users/ivylou/Desktop/pythonProject/testnet2/venv/lib/python3.8/site-packages/sqlalchemy/orm/session.py", line 1451, in commit
    self._transaction.commit(_to_root=self.future)
  File "/Users/ivylou/Desktop/pythonProject/testnet2/venv/lib/python3.8/site-packages/sqlalchemy/orm/session.py", line 829, in commit
    self._prepare_impl()
  File "/Users/ivylou/Desktop/pythonProject/testnet2/venv/lib/python3.8/site-packages/sqlalchemy/orm/session.py", line 808, in _prepare_impl
    self.session.flush()
  File "/Users/ivylou/Desktop/pythonProject/testnet2/venv/lib/python3.8/site-packages/sqlalchemy/orm/session.py", line 3383, in flush
    self._flush(objects)
  File "/Users/ivylou/Desktop/pythonProject/testnet2/venv/lib/python3.8/site-packages/sqlalchemy/orm/session.py", line 3523, in _flush
    transaction.rollback(_capture_exception=True)
  File "/Users/ivylou/Desktop/pythonProject/testnet2/venv/lib/python3.8/site-packages/sqlalchemy/util/langhelpers.py", line 70, in __exit__
    compat.raise_(
  File "/Users/ivylou/Desktop/pythonProject/testnet2/venv/lib/python3.8/site-packages/sqlalchemy/util/compat.py", line 208, in raise_
    raise exception
  File "/Users/ivylou/Desktop/pythonProject/testnet2/venv/lib/python3.8/site-packages/sqlalchemy/orm/session.py", line 3483, in _flush
    flush_context.execute()
  File "/Users/ivylou/Desktop/pythonProject/testnet2/venv/lib/python3.8/site-packages/sqlalchemy/orm/unitofwork.py", line 456, in execute
    rec.execute(self)
  File "/Users/ivylou/Desktop/pythonProject/testnet2/venv/lib/python3.8/site-packages/sqlalchemy/orm/unitofwork.py", line 630, in execute
    util.preloaded.orm_persistence.save_obj(
  File "/Users/ivylou/Desktop/pythonProject/testnet2/venv/lib/python3.8/site-packages/sqlalchemy/orm/persistence.py", line 237, in save_obj
    _emit_update_statements(
  File "/Users/ivylou/Desktop/pythonProject/testnet2/venv/lib/python3.8/site-packages/sqlalchemy/orm/persistence.py", line 1001, in _emit_update_statements
    c = connection._execute_20(
  File "/Users/ivylou/Desktop/pythonProject/testnet2/venv/lib/python3.8/site-packages/sqlalchemy/engine/base.py", line 1631, in _execute_20
    return meth(self, args_10style, kwargs_10style, execution_options)
  File "/Users/ivylou/Desktop/pythonProject/testnet2/venv/lib/python3.8/site-packages/sqlalchemy/sql/elements.py", line 332, in _execute_on_connection
    return connection._execute_clauseelement(
  File "/Users/ivylou/Desktop/pythonProject/testnet2/venv/lib/python3.8/site-packages/sqlalchemy/engine/base.py", line 1498, in _execute_clauseelement
    ret = self._execute_context(
  File "/Users/ivylou/Desktop/pythonProject/testnet2/venv/lib/python3.8/site-packages/sqlalchemy/engine/base.py", line 1862, in _execute_context
    self._handle_dbapi_exception(
  File "/Users/ivylou/Desktop/pythonProject/testnet2/venv/lib/python3.8/site-packages/sqlalchemy/engine/base.py", line 2043, in _handle_dbapi_exception
    util.raise_(
  File "/Users/ivylou/Desktop/pythonProject/testnet2/venv/lib/python3.8/site-packages/sqlalchemy/util/compat.py", line 208, in raise_
    raise exception
  File "/Users/ivylou/Desktop/pythonProject/testnet2/venv/lib/python3.8/site-packages/sqlalchemy/engine/base.py", line 1819, in _execute_context
    self.dialect.do_execute(
  File "/Users/ivylou/Desktop/pythonProject/testnet2/venv/lib/python3.8/site-packages/sqlalchemy/engine/default.py", line 732, in do_execute
    cursor.execute(statement, parameters)
  File "/Users/ivylou/Desktop/pythonProject/testnet2/venv/lib/python3.8/site-packages/mysql/connector/cursor.py", line 561, in execute
    self._handle_result(self._connection.cmd_query(stmt))
  File "/Users/ivylou/Desktop/pythonProject/testnet2/venv/lib/python3.8/site-packages/mysql/connector/connection.py", line 990, in cmd_query
    result = self._handle_result(self._send_cmd(ServerCmd.QUERY, query))
  File "/Users/ivylou/Desktop/pythonProject/testnet2/venv/lib/python3.8/site-packages/mysql/connector/connection.py", line 784, in _handle_result
    raise get_exception(packet)
sqlalchemy.exc.IntegrityError: (mysql.connector.errors.IntegrityError) 1062 (23000): Duplicate entry 'max' for key 'users.ix_users_username'
[SQL: UPDATE users SET username=%(username)s WHERE users.id = %(users_id)s]
[parameters: {'username': 'max', 'users_id': 1}]
(Background on this error at: https://sqlalche.me/e/14/gkpj)
